<?xml version="1.0" ?>
<robot xmlns:xacro="http://ros.org/wiki/xacro">
    <xacro:property name="pi" value="3.14159265358979" />
        <xacro:macro name="P80_800" params="prefix">

        <!-- link list -->
        <link name="${prefix}base_link">
            <visual>
                <origin xyz="0 0 0.11" rpy="${pi} 0 0" />
                <geometry>
                    <mesh 
                        filename="package://gomtec_robot_description/meshes/visual/RGM1656_Base.STL" 
                        scale="0.001 0.001 0.001" />
                </geometry>
                <material name="gomtec_dunkel">
                    <color rgba="0.4 0.4 0.4 1" />
                </material>
            </visual>
            <collision>
                <origin xyz="0 0 0.11" rpy="${pi} 0 0" />
                <geometry>
                    <mesh 
                        filename="package://gomtec_robot_description/meshes/collision/RGM1656_Base.STL" 
                        scale="0.001 0.001 0.001" />
                </geometry>
            </collision>
        </link>

        <link name="${prefix}link_1">
            <visual>
                <origin xyz="0 0 0" rpy="${pi} 0 ${pi}" />
                <geometry>
                    <mesh 
                        filename="package://gomtec_robot_description/meshes/visual/RGM1603_Joint110.STL" 
                        scale="0.001 0.001 0.001" />
                </geometry>
                <material name="gomtec_grau">
                    <color rgba="0.6 0.6 0.5 1" />
                </material>
            </visual>
            <collision>
                <origin xyz="0 0 0" rpy="${pi} 0 ${pi}" />
                <geometry>
                    <mesh 
                        filename="package://gomtec_robot_description/meshes/collision/RGM1603_Joint110.STL" 
                        scale="0.001 0.001 0.001" />
                </geometry>
            </collision>
        </link>

        <link name="${prefix}link_2">
            <visual>
                <origin xyz="0 0.135 0.01" rpy="${-pi} ${-pi/2} ${pi/2}" />
                <geometry>
                    <mesh 
                        filename="package://gomtec_robot_description/meshes/visual/RGM1649_Arm1.STL" 
                        scale="0.001 0.001 0.001" />
                </geometry>
                <material name="gomtec_grau">
                    <color rgba="0.6 0.6 0.5 1" />
                </material>
            </visual>
            <collision>
                <origin xyz="0 0.135 0.01" rpy="${-pi} ${-pi/2} ${pi/2}" />
                <geometry>
                    <mesh 
                        filename="package://gomtec_robot_description/meshes/collision/RGM1649_Arm1.STL" 
                        scale="0.001 0.001 0.001" />
                </geometry>
            </collision>
        </link>

        <link name="${prefix}link_3">
            <visual>
                <origin xyz="0 0.1 -0.02" rpy="${-pi/2} 0 0" />
                <geometry>
                    <mesh 
                        filename="package://gomtec_robot_description/meshes/visual/RGM1590_Joint90.STL" 
                        scale="0.001 0.001 0.001" />
                </geometry>
                <material name="gomtec_grau">
                    <color rgba="0.6 0.6 0.5 1" />
                </material>
            </visual>
            <collision>
                <origin xyz="0 0.1 -0.02" rpy="${-pi/2} 0 0" />
                <geometry>
                    <mesh 
                        filename="package://gomtec_robot_description/meshes/collision/RGM1590_Joint90.STL" 
                        scale="0.001 0.001 0.001" />
                </geometry>
            </collision>
        </link>

        <link name="${prefix}link_4">
            <visual>
                <origin xyz="0.25 -0.0115 -0.005" rpy="0 ${-pi/2} 0" />
                <geometry>
                    <mesh 
                        filename="package://gomtec_robot_description/meshes/visual/RGM1650_Arm2.STL" 
                        scale="0.001 0.001 0.001" />
                </geometry>
                <material name="gomtec_grau">
                    <color rgba="0.6 0.6 0.5 1" />
                </material>
            </visual>
            <collision>
                <origin xyz="0.25 -0.0115 -0.005" rpy="0 ${-pi/2} 0" />
                <geometry>
                    <mesh 
                        filename="package://gomtec_robot_description/meshes/collision/RGM1650_Arm2.STL" 
                        scale="0.001 0.001 0.001" />
                </geometry>
            </collision>
        </link>

        <link name="${prefix}link_5">
            <visual>
                <origin xyz="0 0 0.007" rpy="${-pi/2} 0 ${-pi}" />
                <geometry>
                    <mesh 
                        filename="package://gomtec_robot_description/meshes/visual/RGM1631_Joint70.STL" 
                        scale="0.001 0.001 0.001" />
                </geometry>
               <material name="gomtec_grau">
                    <color rgba="0.6 0.6 0.5 1" />
                </material>
            </visual>
            <collision>
                <origin xyz="0 0 0.007" rpy="${-pi/2} 0 ${-pi}" />
                <geometry>
                    <mesh 
                        filename="package://gomtec_robot_description/meshes/collision/RGM1631_Joint70.STL" 
                        scale="0.001 0.001 0.001" />
                </geometry>
            </collision>
        </link>

        <link name="${prefix}link_flange" />
		<!-- end of link list -->

		<!-- joint list -->
        <joint name="${prefix}joint_1" type="continuous">
            <parent link="${prefix}base_link" />
            <child link="${prefix}link_1" />
            <origin rpy="0 0 0" xyz="0 0 0.185" />
            <axis xyz="0 0 1" />
            <limit effort="0" velocity="${100*pi/180}" />
        </joint>

        <joint name="${prefix}joint_2" type="continuous">
            <parent link="${prefix}link_1" />
            <child link="${prefix}link_2" />
            <origin rpy="0 0 0" xyz="0 0 0.45" />
            <axis xyz="0 1 0" />
            <limit effort="0" velocity="${100*pi/180}"/>
        </joint>

        <joint name="${prefix}joint_3" type="continuous">
            <parent link="${prefix}link_2" />
            <child link="${prefix}link_3" />
            <origin rpy="0 0 0" xyz="0 0 0.38" />
            <axis xyz="0 -1 0" />
            <limit effort="0" velocity="${100*pi/180}"/>
        </joint>

        <joint name="${prefix}joint_4" type="continuous">
            <parent link="${prefix}link_3" />
            <child link="${prefix}link_4" />
            <origin rpy="0 0 0" xyz="0 0.025 -0.01" />
            <axis xyz="1 0 0" />
            <limit effort="0" velocity="${100*pi/180}"/>
        </joint>

        <joint name="${prefix}joint_5" type="continuous">
            <parent link="${prefix}link_4" />
            <child link="${prefix}link_5" />
            <origin rpy="0 0 0" xyz="0.30 0.005 -0.006" />
            <axis xyz="0 1 0" />
            <limit effort="0" velocity="${200*pi/180}"/>
        </joint>

        <joint name="${prefix}joint_6" type="continuous">
            <parent link="${prefix}link_5" />
            <child link="${prefix}link_flange" />
            <origin rpy="0 0 0" xyz="0.07 -0.002 0.000" />
            <axis xyz="1 0 0" />
            <limit effort="0" velocity="${200*pi/180}" />
        </joint>
		<!-- end of joint list -->

        <gazebo reference="${prefix}base_link">
            <material>Gazebo/Yellow</material>
        </gazebo>
        <gazebo reference="${prefix}link_1">
            <material>Gazebo/Red</material>
        </gazebo>
        <gazebo reference="${prefix}link_2">
            <material>Gazebo/Blue</material>
        </gazebo>
        <gazebo reference="${prefix}link_3">
            <material>Gazebo/Red</material>
        </gazebo>
        <gazebo reference="${prefix}link_4">
            <material>Gazebo/Blue</material>
        </gazebo>
        <gazebo reference="${prefix}link_5">
            <material>Gazebo/Red</material>
        </gazebo>
        <gazebo reference="${prefix}link_flange">
            <material>Gazebo/Yellow</material>
        </gazebo>
	</xacro:macro>
</robot>

